<?xml version="1.0"?>
<robot name="test_robot">
  <!-- Base Link -->
  <link name="base_link">
    <visual>
      <geometry>
        <cylinder length="0.1" radius="0.2"/>
      </geometry>
      <material name="gray">
        <color rgba="0.5 0.5 0.5 1.0"/>
      </material>
    </visual>
    <collision>
      <geometry>
        <cylinder length="0.1" radius="0.2"/>
      </geometry>
    </collision>
    <inertial>
      <mass value="5.0"/>
      <inertia ixx="0.1" ixy="0.0" ixz="0.0" iyy="0.1" iyz="0.0" izz="0.1"/>
    </inertial>
  </link>

  <!-- Joint 1: Base to Link 1 -->
  <joint name="joint1" type="revolute">
    <parent link="base_link"/>
    <child link="link1"/>
    <origin xyz="0 0 0.1" rpy="0 0 0"/>
    <axis xyz="0 0 1"/>
    <limit lower="-3.14" upper="3.14" effort="100" velocity="1"/>
  </joint>

  <!-- Link 1 -->
  <link name="link1">
    <visual>
      <geometry>
        <box size="0.1 0.1 0.4"/>
      </geometry>
      <origin xyz="0 0 0.2" rpy="0 0 0"/>
      <material name="red">
        <color rgba="1.0 0.0 0.0 1.0"/>
      </material>
    </visual>
    <collision>
      <geometry>
        <box size="0.1 0.1 0.4"/>
      </geometry>
      <origin xyz="0 0 0.2" rpy="0 0 0"/>
    </collision>
    <inertial>
      <mass value="1.0"/>
      <origin xyz="0 0 0.2" rpy="0 0 0"/>
      <inertia ixx="0.01" ixy="0.0" ixz="0.0" iyy="0.01" iyz="0.0" izz="0.005"/>
    </inertial>
  </link>

  <!-- Joint 2: Link 1 to Link 2 -->
  <joint name="joint2" type="revolute">
    <parent link="link1"/>
    <child link="link2"/>
    <origin xyz="0 0 0.4" rpy="0 0 0"/>
    <axis xyz="0 1 0"/>
    <limit lower="-1.57" upper="1.57" effort="100" velocity="1"/>
  </joint>

  <!-- Link 2 -->
  <link name="link2">
    <visual>
      <geometry>
        <box size="0.4 0.1 0.1"/>
      </geometry>
      <origin xyz="0.2 0 0" rpy="0 0 0"/>
      <material name="green">
        <color rgba="0.0 1.0 0.0 1.0"/>
      </material>
    </visual>
    <collision>
      <geometry>
        <box size="0.4 0.1 0.1"/>
      </geometry>
      <origin xyz="0.2 0 0" rpy="0 0 0"/>
    </collision>
    <inertial>
      <mass value="1.0"/>
      <origin xyz="0.2 0 0" rpy="0 0 0"/>
      <inertia ixx="0.005" ixy="0.0" ixz="0.0" iyy="0.01" iyz="0.0" izz="0.01"/>
    </inertial>
  </link>

  <!-- Joint 3: Link 2 to Link 3 -->
  <joint name="joint3" type="revolute">
    <parent link="link2"/>
    <child link="link3"/>
    <origin xyz="0.4 0 0" rpy="0 0 0"/>
    <axis xyz="0 0 1"/>
    <limit lower="-3.14" upper="3.14" effort="100" velocity="1"/>
  </joint>

  <!-- Link 3 -->
  <link name="link3">
    <visual>
      <geometry>
        <box size="0.1 0.1 0.4"/>
      </geometry>
      <origin xyz="0 0 0.2" rpy="0 0 0"/>
      <material name="blue">
        <color rgba="0.0 0.0 1.0 1.0"/>
      </material>
    </visual>
    <collision>
      <geometry>
        <box size="0.1 0.1 0.4"/>
      </geometry>
      <origin xyz="0 0 0.2" rpy="0 0 0"/>
    </collision>
    <inertial>
      <mass value="1.0"/>
      <origin xyz="0 0 0.2" rpy="0 0 0"/>
      <inertia ixx="0.01" ixy="0.0" ixz="0.0" iyy="0.01" iyz="0.0" izz="0.005"/>
    </inertial>
  </link>

  <!-- Joint 4: Link 3 to Link 4 -->
  <joint name="joint4" type="revolute">
    <parent link="link3"/>
    <child link="link4"/>
    <origin xyz="0 0 0.4" rpy="0 0 0"/>
    <axis xyz="0 1 0"/>
    <limit lower="-1.57" upper="1.57" effort="100" velocity="1"/>
  </joint>

  <!-- Link 4 -->
  <link name="link4">
    <visual>
      <geometry>
        <box size="0.4 0.1 0.1"/>
      </geometry>
      <origin xyz="0.2 0 0" rpy="0 0 0"/>
      <material name="yellow">
        <color rgba="1.0 1.0 0.0 1.0"/>
      </material>
    </visual>
    <collision>
      <geometry>
        <box size="0.4 0.1 0.1"/>
      </geometry>
      <origin xyz="0.2 0 0" rpy="0 0 0"/>
    </collision>
    <inertial>
      <mass value="1.0"/>
      <origin xyz="0.2 0 0" rpy="0 0 0"/>
      <inertia ixx="0.005" ixy="0.0" ixz="0.0" iyy="0.01" iyz="0.0" izz="0.01"/>
    </inertial>
  </link>

  <!-- Joint 5: Link 4 to Link 5 -->
  <joint name="joint5" type="revolute">
    <parent link="link4"/>
    <child link="link5"/>
    <origin xyz="0.4 0 0" rpy="0 0 0"/>
    <axis xyz="0 0 1"/>
    <limit lower="-3.14" upper="3.14" effort="100" velocity="1"/>
  </joint>

  <!-- Link 5 -->
  <link name="link5">
    <visual>
      <geometry>
        <box size="0.1 0.1 0.2"/>
      </geometry>
      <origin xyz="0 0 0.1" rpy="0 0 0"/>
      <material name="purple">
        <color rgba="0.5 0.0 0.5 1.0"/>
      </material>
    </visual>
    <collision>
      <geometry>
        <box size="0.1 0.1 0.2"/>
      </geometry>
      <origin xyz="0 0 0.1" rpy="0 0 0"/>
    </collision>
    <inertial>
      <mass value="0.5"/>
      <origin xyz="0 0 0.1" rpy="0 0 0"/>
      <inertia ixx="0.005" ixy="0.0" ixz="0.0" iyy="0.005" iyz="0.0" izz="0.002"/>
    </inertial>
  </link>

  <!-- Joint 6: Link 5 to Link 6 -->
  <joint name="joint6" type="revolute">
    <parent link="link5"/>
    <child link="link6"/>
    <origin xyz="0 0 0.2" rpy="0 0 0"/>
    <axis xyz="0 1 0"/>
    <limit lower="-1.57" upper="1.57" effort="100" velocity="1"/>
  </joint>

  <!-- Link 6 (End effector link) -->
  <link name="link6">
    <visual>
      <geometry>
        <cylinder length="0.05" radius="0.05"/>
      </geometry>
      <origin xyz="0 0 0.025" rpy="0 0 0"/>
      <material name="cyan">
        <color rgba="0.0 1.0 1.0 1.0"/>
      </material>
    </visual>
    <collision>
      <geometry>
        <cylinder length="0.05" radius="0.05"/>
      </geometry>
      <origin xyz="0 0 0.025" rpy="0 0 0"/>
    </collision>
    <inertial>
      <mass value="0.2"/>
      <origin xyz="0 0 0.025" rpy="0 0 0"/>
      <inertia ixx="0.001" ixy="0.0" ixz="0.0" iyy="0.001" iyz="0.0" izz="0.001"/>
    </inertial>
  </link>

  <!-- Tool0 Frame (End effector frame) -->
  <joint name="joint_tool0" type="fixed">
    <parent link="link6"/>
    <child link="tool0"/>
    <origin xyz="0 0 0.05" rpy="0 0 0"/>
  </joint>

  <!-- Tool0 Link -->
  <link name="tool0">
    <!-- This is just a frame, no geometry needed -->
  </link>
</robot>